Workbook
Name currency: Assumptions!$F$16

Sheet Cover Page
B3: Lexa Bottling Co.
B5: ="Financial Model from "&D9+1&" to "&D9+5 -> Financial Model from 2025 to 2029
B7: Modeler | D7: Ovoke Ohwoganohwo
B9: Base Year | D9: 2024

Sheet Assumptions
B2: ='Cover Page'!B3 -> Lexa Bottling Co. | I2: ="Financial Model :"&J5&" to "&N5 -> Financial Model :2025 to 2029
B3: Assumptions
I4: Actual | J4: Forecast | K4: Forecast | L4: Forecast | M4: Forecast | N4: Forecast
E5: Units | F5: Inputs | I5: 2024 | J5: 2025 | K5: 2026 | L5: 2027 | M5: 2028 | N5: 2029
B8: Cells Styles
D10: Number | E10: Number | F10: 1234.56
D11: Inputs | E11: Number | F11: 1234.56
D12: Multiple | E12: Number | F12: 12.34
D13: Percentage | E13: Number | F13: 0.1234
D14: Linked | E14: Number | F14: 1234.56
D15: Units | E15: Text | F15: Text
D16: Currency | F16: ₦'mn
C19: Revenue Assumptions
D21: Forecast Rate | E21: % | J21: 0.2 | K21: 0.15 | L21: 0.12 | M21: 0.1 | N21: 0.08
D23: Historical Figure | E23: =currency -> ₦'mn | I23: 2200
C25: Gross Margin Assumption
D27: Forecast Rate | E27: % of Revenue | I27: 0.34 | J27: 0.34 | K27: 0.35 | L27: 0.355 | M27: 0.36 | N27: 0.36
C30: EBITDA Margin Assumption
D32: Forecast Rate | E32: % of Revenue | I32: 0.18 | J32: 0.1855 | K32: 0.19 | L32: 0.2 | M32: 0.21 | N32: 0.23
C35: CAPEX Assumption
D37: Additions | E37: =currency -> ₦'mn | J37: 1200
D39: Depreciation Method | E39: Staright Line Method
C41: Useful Life | E41: Years | F41: 7
D43: Depreciation | E43: =currency -> ₦'mn | I43: 75 | J43: =$J$37/$F$41 -> 171.42857 | K43: =$J$37/$F$41 -> 171.42857 | L43: =$J$37/$F$41 -> 171.42857 | M43: =$J$37/$F$41 -> 171.42857 | N43: =$J$37/$F$41 -> 171.42857
D45: Opening Balance | E45: =currency -> ₦'mn | I45: =H48 -> 500 | J45: =I48 -> 425 | K45: =J48 -> 1453.5714 | L45: =K48 -> 1282.1429 | M45: =L48 -> 1110.7143 | N45: =M48 -> 939.28571
D46: =D37 -> Additions | E46: =E37 -> ₦'mn | I46: 0 | J46: =J37 -> 1200 | K46: =K37 -> 0 | L46: =L37 -> 0 | M46: =M37 -> 0 | N46: =N37 -> 0
D47: =D43 -> Depreciation | E47: =currency -> ₦'mn | I47: =I43 -> 75 | J47: =J43 -> 171.42857 | K47: =K43 -> 171.42857 | L47: =L43 -> 171.42857 | M47: =M43 -> 171.42857 | N47: =N43 -> 171.42857
D48: Closing Balance | E48: =currency -> ₦'mn | H48: 500 | I48: =I45+I46-I47 -> 425 | J48: =J45+J46-J47 -> 1453.5714 | K48: =K45+K46-K47 -> 1282.1429 | L48: =L45+L46-L47 -> 1110.7143 | M48: =M45+M46-M47 -> 939.28571 | N48: =N45+N46-N47 -> 767.85714
C52: Working Capital Assumption
D54: Forecast Rate | I54: 0.12 | J54: 0.12 | K54: 0.1175 | L54: 0.115 | M54: 0.1065 | N54: 0.1
B56: A
C57: Debt Assumption
D59: Existing debt outstanding (NGN) | E59: =currency -> ₦'mn | I59: 500
D61: Interest rate on existing debt | E61: % | F61: 0.13
D63: Interest Expense on Existing Debt | E63: =currency -> ₦'mn | I63: =$I$59*$F$61 -> 65 | J63: =$I$59*$F$61 -> 65 | K63: =$I$59*$F$61 -> 65 | L63: =$I$59*$F$61 -> 65 | M63: =$I$59*$F$61 -> 65 | N63: =$I$59*$F$61 -> 65
D65: New External Capital - Debt | E65: =currency -> ₦'mn | J65: 1500
D67: Interest rate on new debt | E67: % | F67: 0.325
D69: Interest Expense on New Debt | E69: =currency -> ₦'mn | J69: =$F$67*$J$65 -> 487.5 | K69: =$F$67*$J$65 -> 487.5 | L69: =$F$67*$J$65 -> 487.5 | M69: =$F$67*$J$65 -> 487.5 | N69: =$F$67*$J$65 -> 487.5
D71: =D74 -> Interest Expense | E71: =E74 -> ₦'mn | I71: =I63+I69 -> 65 | J71: =J63+J69 -> 552.5 | K71: =K63+K69 -> 552.5 | L71: =L63+L69 -> 552.5 | M71: =M63+M69 -> 552.5 | N71: =N63+N69 -> 552.5
D72: Tax Impact | E72: % | J72: 0.3 | K72: 0.3 | L72: 0.3 | M72: 0.3 | N72: 0.3
...

Sheet Model
B2: ='Cover Page'!B3 -> Lexa Bottling Co. | I2: ="Financial Model :"&J5&" to "&N5 -> Financial Model :2025 to 2029
B3: Model
I4: Actual | J4: Forecast | K4: Forecast | L4: Forecast | M4: Forecast | N4: Forecast
E5: Units | F5: Inputs | I5: 2024 | J5: 2025 | K5: 2026 | L5: 2027 | M5: 2028 | N5: 2029
B7: Statement of Profit or Loss
D9: Revenue | E9: =currency -> ₦'mn | I9: =Assumptions!I23 -> 2200 | J9: =I9*(1+Assumptions!J21) -> 2640 | K9: =J9*(1+Assumptions!K21) -> 3036 | L9: =K9*(1+Assumptions!L21) -> 3400.32 | M9: =L9*(1+Assumptions!M21) -> 3740.352 | N9: =M9*(1+Assumptions!N21) -> 4039.5802
D10: Cost of Sales | E10: =currency -> ₦'mn | I10: =I9*(1-Assumptions!I27) -> 1452 | J10: =J9*(1-Assumptions!J27) -> 1742.4 | K10: =K9*(1-Assumptions!K27) -> 1973.4 | L10: =L9*(1-Assumptions!L27) -> 2193.2064 | M10: =M9*(1-Assumptions!M27) -> 2393.8253 | N10: =N9*(1-Assumptions!N27) -> 2585.3313
D11: Gross Profit | E11: =currency -> ₦'mn | I11: =I9*Assumptions!I27 -> 748 | J11: =J9*Assumptions!J27 -> 897.6 | K11: =K9*Assumptions!K27 -> 1062.6 | L11: =L9*Assumptions!L27 -> 1207.1136 | M11: =M9*Assumptions!M27 -> 1346.5267 | N11: =N9*Assumptions!N27 -> 1454.2489
D13: Operating Expenses | E13: =currency -> ₦'mn | I13: =I11-I14 -> 352 | J13: =J11-J14 -> 407.88 | K13: =K11-K14 -> 485.76 | L13: =L11-L14 -> 527.0496 | M13: =M11-M14 -> 561.0528 | N13: =N11-N14 -> 525.14542
D14: EBITDA | E14: =currency -> ₦'mn | I14: =I9*Assumptions!I32 -> 396 | J14: =J9*Assumptions!J32 -> 489.72 | K14: =K9*Assumptions!K32 -> 576.84 | L14: =L9*Assumptions!L32 -> 680.064 | M14: =M9*Assumptions!M32 -> 785.47392 | N14: =N9*Assumptions!N32 -> 929.10344
D16: Depreciation | E16: =currency -> ₦'mn | I16: =Assumptions!I43 -> 75 | J16: =Assumptions!J43 -> 171.42857 | K16: =Assumptions!K43 -> 171.42857 | L16: =Assumptions!L43 -> 171.42857 | M16: =Assumptions!M43 -> 171.42857 | N16: =Assumptions!N43 -> 171.42857
D17: EBIT | E17: =currency -> ₦'mn | I17: =I14-I16 -> 321 | J17: =J14-J16 -> 318.29143 | K17: =K14-K16 -> 405.41143 | L17: =L14-L16 -> 508.63543 | M17: =M14-M16 -> 614.04535 | N17: =N14-N16 -> 757.67487
D19: =Assumptions!D74 -> Interest Expense | E19: =Assumptions!E74 -> ₦'mn | I19: =Assumptions!I74 -> 65 | J19: =Assumptions!J74 -> 386.75 | K19: =Assumptions!K74 -> 386.75 | L19: =Assumptions!L74 -> 386.75 | M19: =Assumptions!M74 -> 386.75 | N19: =Assumptions!N74 -> 386.75
D20: Net Income | E20: =currency -> ₦'mn | I20: =I17-I19 -> 256 | J20: =J17-J19 -> -68.458571 | K20: =K17-K19 -> 18.661429 | L20: =L17-L19 -> 121.88543 | M20: =M17-M19 -> 227.29535 | N20: =N17-N19 -> 370.92487
I22: =
B23: Statement of Financial Position
A24: A
C25: Assets
D26: PPE | E26: =currency -> ₦'mn | I26: =Assumptions!I48 -> 425 | J26: =Assumptions!J48 -> 1453.5714 | K26: =Assumptions!K48 -> 1282.1429 | L26: =Assumptions!L48 -> 1110.7143 | M26: =Assumptions!M48 -> 939.28571 | N26: =Assumptions!N48 -> 767.85714
D27: Cash and Cash Equivalent | E27: =currency -> ₦'mn | I27: =I33-I26 -> 266 | J27: =J33-J26 -> 26.22 | K27: =K33-K26 -> -101.98143 | L27: =L33-L26 -> -214.07886 | M27: =M33-M26 -> -323.99037 | N27: =N33-N26 -> -395.68228
C28: Total Assets | E28: =currency -> ₦'mn | I28: =SUM(I26:I27) -> 691 | J28: =SUM(J26:J27) -> 1479.7914 | K28: =SUM(K26:K27) -> 1180.1614 | L28: =SUM(L26:L27) -> 896.63543 | M28: =SUM(M26:M27) -> 615.29535 | N28: =SUM(N26:N27) -> 372.17487
C30: Liabilities | E30: =currency -> ₦'mn | I30: =Assumptions!I79 -> 435 | J30: =Assumptions!J79 -> 1548.25 | K30: =Assumptions!K79 -> 1161.5 | L30: =Assumptions!L79 -> 774.75 | M30: =Assumptions!M79 -> 388 | N30: =Assumptions!N79 -> 1.25
C31: Equity | E31: =currency -> ₦'mn | I31: 0 | J31: 0 | K31: 0 | L31: 0 | M31: 0 | N31: 0
D32: =D20 -> Net Income | E32: =currency -> ₦'mn | I32: =I20 -> 256 | J32: =J20 -> -68.458571 | K32: =K20 -> 18.661429 | L32: =L20 -> 121.88543 | M32: =M20 -> 227.29535 | N32: =N20 -> 370.92487
C33: Total Equity and Liabilities | E33: =currency -> ₦'mn | I33: =SUM(I30:I32) -> 691 | J33: =SUM(J30:J32) -> 1479.7914 | K33: =SUM(K30:K32) -> 1180.1614 | L33: =SUM(L30:L32) -> 896.63543 | M33: =SUM(M30:M32) -> 615.29535 | N33: =SUM(N30:N32) -> 372.17487
C35: Check | I35: =I28-I33 -> 0 | J35: =J28-J33 -> 0 | K35: =K28-K33 -> 0 | L35: =L28-L33 -> 0 | M35: =M28-M33 -> 0 | N35: =N28-N33 -> 0
B38: Statement of Cashflow
D40: =D27 -> Cash and Cash Equivalent | E40: =currency -> ₦'mn | I40: =I27 -> 266 | J40: =J27 -> 26.22 | K40: =K27 -> -101.98143 | L40: =L27 -> -214.07886 | M40: =M27 -> -323.99037 | N40: =N27 -> -395.68228

Sheet Valuation
B2: ='Cover Page'!B3 -> Lexa Bottling Co. | I2: ="Financial Model :"&J5&" to "&N5 -> Financial Model :2025 to 2029
B3: Valuation
I4: Actual | J4: Forecast | K4: Forecast | L4: Forecast | M4: Forecast | N4: Forecast
E5: Units | F5: Inputs | I5: 2024 | J5: 2025 | K5: 2026 | L5: 2027 | M5: 2028 | N5: 2029
D7: Valuation Date | F7: =TODAY() -> 46036
D9: =Model!D14 -> EBITDA | E9: =currency -> ₦'mn | I9: =Model!I14 -> 396 | J9: =Model!J14 -> 489.72 | K9: =Model!K14 -> 576.84 | L9: =Model!L14 -> 680.064 | M9: =Model!M14 -> 785.47392 | N9: =Model!N14 -> 929.10344
D10: EBIAT (NOPAT) | E10: =currency -> ₦'mn | I10: =I9*(1-0.3) -> 277.2 | J10: =J9*(1-0.3) -> 342.804 | K10: =K9*(1-0.3) -> 403.788 | L10: =L9*(1-0.3) -> 476.0448 | M10: =M9*(1-0.3) -> 549.83174 | N10: =N9*(1-0.3) -> 650.37241
D12: =Model!D16 -> Depreciation | E12: =Model!E16 -> ₦'mn | I12: =Model!I16 -> 75 | J12: =Model!J16 -> 171.42857 | K12: =Model!K16 -> 171.42857 | L12: =Model!L16 -> 171.42857 | M12: =Model!M16 -> 171.42857 | N12: =Model!N16 -> 171.42857
D13: Unlevered CFO | I13: =I10+I12 -> 352.2 | J13: =J10+J12 -> 514.23257 | K13: =K10+K12 -> 575.21657 | L13: =L10+L12 -> 647.47337 | M13: =M10+M12 -> 721.26032 | N13: =N10+N12 -> 821.80098
D14: Less: Capital expenditures | I14: =Assumptions!I37 -> 0 | J14: =Assumptions!J37 -> 1200 | K14: =Assumptions!K37 -> 0 | L14: =Assumptions!L37 -> 0 | M14: =Assumptions!M37 -> 0 | N14: =Assumptions!N37 -> 0
D16: Unlevered FCF | I16: =I13-I14 -> 352.2 | J16: =J13-J14 -> -685.76743 | K16: =K13-K14 -> 575.21657 | L16: =L13-L14 -> 647.47337 | M16: =M13-M14 -> 721.26032 | N16: =N13-N14 -> 821.80098
J18: 1 | K18: 2 | L18: 3 | M18: 4 | N18: 5
D20: Discount factor (WACC) | E20: % | I20: 0.325 | J20: 0.325 | K20: 0.325 | L20: 0.325 | M20: 0.325 | N20: 0.325
D22: PV of FCF | E22: =currency -> ₦'mn | J22: =J16/(1+J20)^J18 -> -517.56032 | K22: =K16/(1+K20)^K18 -> 327.64205 | L22: =L16/(1+L20)^L18 -> 278.33914 | M22: =M16/(1+M20)^M18 -> 234.00683 | N22: =N16/(1+N20)^N18 -> 201.22747
D24: Enterprise value | E24: =currency -> ₦'mn | N24: =SUM(I22:N22) -> 523.65516
D29: WITHOUT CONSIDERING DEBT
D31: =D22 -> PV of FCF | E31: =currency -> ₦'mn | J31: =J22 -> -517.56032 | K31: =K22 -> 327.64205 | L31: =L22 -> 278.33914 | M31: =M22 -> 234.00683 | N31: =N22 -> 201.22747
D33: =D24 -> Enterprise value | E33: =E24 -> ₦'mn | N33: =N24 -> 523.65516
D34: Debt Value | E34: =currency -> ₦'mn | N34: 0
D35: Equity Value | N35: =SUM(N33:N34) -> 523.65516
